Workbook

Sheet 환율
A1: 환율 및 기본 가정
A3: 항목 | B3: 값 | C3: 비고
A4: 조지아 라리 (GEL) → 원 | B4: 541 | C4: 2026년 8월 6일 조지아·아르메니아 중앙은행 공시 기준 (USD/KRW 1,420 교차 산출)
A5: 아르메니아 드람 (AMD) → 원 | B5: 3.88 | C5: 2026년 8월 6일 조지아·아르메니아 중앙은행 공시 기준 (USD/KRW 1,420 교차 산출)
A6: 유로 (EUR) → 원 | B6: 1640 | C6: 2026년 8월 6일 시장환율 — 아테네 구간
A7: UAE 디르함 (AED) → 원 | B7: 387 | C7: 2026년 8월 6일 시장환율 (USD 페그 3.6725) — 아부다비 구간
A8: 중국 위안 (CNY) → 원 | B8: 211 | C8: 2026년 8월 6일 시장환율 — 상하이 경유 구간
A9: 인원 | B9: 1 | C9: 1인 여행 — 택시·기사 비용을 나눌 사람이 없어 전액 부담
A10: 항공권1 — 김포→상하이 + 푸동→트빌리시 (별도 발권 2편) | B10: 446000 | C10: 결제 완료 — 원화 확정. 김포→상하이 + 푸동→트빌리시 2편 합산
A11: 항공권2 — 예레반→아테네 (에게안 A3 3899 · XD9TVH) | B11: 303900 | C11: 결제 완료 — 원화 확정
A12: 항공권3 — 아테네→아부다비→인천 (아부다비 1박 포함) | B12: 656700 | C12: 결제 완료 — 원화 확정. 환율이 바뀌어도 이 금액은 그대로
A13: 항공권 합계 | B13: =SUM(B10:B12) | C13: 3편 모두 결제 완료. 이후 환율 변동은 현지 지출에만 영향
A14: 총예산 (1인) | B14: 3000000 | C14: 사용자 제시: 300만원
A16: 노란 셀만 수정하세요. 나머지 시트는 이 값을 참조해 자동 계산됩니다.
A17: 환율은 현지 지출에만 적용됩니다 (항공권은 결제 완료로 원화 확정). 전 통화 2026년 8월 6일 기준 — 출발 직전에 한 번 더 갱신하세요.
A18: 여행 직전 실제 환율로 한 번 더 갱신하는 것을 권장합니다 — 환율은 매일 바뀝니다.

Sheet 교통상세
A1: 구간별 교통 — 대중교통 우선
A2: ‘대중교통’ 열이 ○ 이면 마르슈르트카·버스·지하철로 갈 수 있는 구간, △ 는 부분적, ✕ 는 택시가 사실상 필수인 구간입니다. 택시 요금은 환율 시트의 인원(현재 1명)으로 나눈 1인 부담액입니다.
A4: 날짜 | B4: 구간 | C4: 수단 | D4: 구분 | E4: 현지 금액 | F4: 통화 | G4: 1인 원화 | H4: 대중교통 | I4: 비고
A5: 9/19 | B5: 훙차오 공항 T1 → 난징둥루 | C5: 지하철 10호선 | D5: 시내 | E5: 5 | F5: CNY | G5: =ROUND(E5*환율!$B$8/1,0) | H5: ○ | I5: 환승 없이 직통, 약 45분
A6: 9/19 | B6: 상하이 시내 이동 (예원·와이탄) | C6: 지하철 10호선 · 도보 | D6: 시내 | E6: 8 | F6: CNY | G6: =ROUND(E6*환율!$B$8/1,0) | H6: ○ | I6: 1회 3~4위안. 대부분 도보권
A7: 9/20 | B7: 시내 → 푸동 국제공항 | C7: 지하철 2호선 | D7: 시내 | E7: 8 | F7: CNY | G7: =ROUND(E7*환율!$B$8/1,0) | H7: ○ | I7: 광란루역에서 열차 갈아탐, 1시간 15분
A8: 9/20 | B8: 공항 → 트빌리시 시내 | C8: 버스 37번 | D8: 시내 | E8: 1 | F8: GEL | G8: =ROUND(E8*환율!$B$4/1,0) | H8: ○ | I8: 24시간 운행
A9: 9/21 | B9: 트빌리시 시내 | C9: 지하철·버스 (메트로머니) | D9: 시내 | E9: 4 | F9: GEL | G9: =ROUND(E9*환율!$B$4/1,0) | H9: ○ | I9: 1회 1라리, 90분 내 환승 무료
A10: 9/22 | B10: 디두베 → 므츠헤타 왕복 | C10: 마르슈르트카 | D10: 시외 | E10: 3 | F10: GEL | G10: =ROUND(E10*환율!$B$4/1,0) | H10: ○ | I10: 20분 간격, 30분 소요
A11: 9/22 | B11: 므츠헤타 → 즈바리 수도원 왕복 | C11: 택시 (대기 포함) | D11: 시내 | E11: 25 | F11: GEL | G11: =ROUND(E11*환율!$B$4/1,0) | H11: ✕ | I11: 대중교통 없음 · 1인 단독이라 전액 부담
A12: 9/23 | B12: 디두베 → 스테판츠민다 | C12: 마르슈르트카 | D12: 시외 | E12: 15 | F12: GEL | G12: =ROUND(E12*환율!$B$4/1,0) | H12: ○ | I12: 3.5~4시간 · 06:40 터미널 도착해 첫 편 탑승 권장
A13: 9/23 | B13: 스테판츠민다 → 게르게티 교회 | C13: 4WD (편도) · 하산은 도보 | D13: 시내 | E13: 25 | F13: GEL | G13: =ROUND(E13*환율!$B$4/1,0) | H13: ○ | I13: 카즈베기 1박이라 도착일 오후에 확정 이용. 하산은 도보. 흐리면 B안(1박 연장)
A14: 9/24 | B14: 스테판츠민다 → 트빌리시 | C14: 마르슈르트카 | D14: 시외 | E14: 15 | F14: GEL | G14: =ROUND(E14*환율!$B$4/1,0) | H14: ○ | I14: 주타 복귀 후 14:00 편 · 약 3~3.5시간
A15: 9/24 | B15: 트빌리시 시내 (디두베 → 숙소) | C15: 지하철·버스 | D15: 시내 | E15: 2 | F15: GEL | G15: =ROUND(E15*환율!$B$4/1,0) | H15: ○ | I15: 지하철
A16: 9/26 | B16: 오르타찰라 → 알라베르디 | C16: 합승택시 (예레반행) | D16: 시외 | E16: 40 | F16: GEL | G16: =ROUND(E16*환율!$B$4/1,0) | H16: ○ | I16: 오전 정시편(08:20) 이용 — 대기 불확실성 해소
A17: 9/26 | B17: 알라베르디 → 사나힌 왕복 | C17: 3번 버스 | D17: 시내 | E17: 400 | F17: AMD | G17: =ROUND(E17*환율!$B$5/1,0) | H17: ○ | I17: 왕복 400드람 · 택시로 하흐파트와 묶으면 6,000드람 안팎
A18: 9/26 | B18: 알라베르디 → 하흐파트 왕복 | C18: 마르슈르트카 | D18: 시외 | E18: 400 | F18: AMD | G18: =ROUND(E18*환율!$B$5/1,0) | H18: ○ | I18: 주말 3편(9·13·17시)뿐
A19: 9/27 | B19: 알라베르디 → 예레반 | C19: 마르슈르트카 | D19: 시외 | E19: 1900 | F19: AMD | G19: =ROUND(E19*환율!$B$5/1,0) | H19: ○ | I19: 첫차 07:30 · 스피타크·아파란 경유 약 4시간 · 직행 없으면 바나조르 환승
A20: 10/2 | B20: 예레반 → 세반 왕복 | C20: 마르슈르트카 | D20: 시외 | E20: 2500 | F20: AMD | G20: =ROUND(E20*환율!$B$5/1,0) | H20: ○ | I20: 편도 1,000~1,500드람 · 편도 1~1.5시간
A21: 10/2 | B21: 세반 → 세바나방크 반도 | C21: 도보 또는 택시 | D21: 시내 | E21: 1000 | F21: AMD | G21: =ROUND(E21*환율!$B$5/1,0) | H21: △ | I21: 도보 30분 · 1인 단독이라 전액 부담
A22: 9/27 | B22: 킬리키아 터미널 → 시내 | C22: 버스 | D22: 시내 | E22: 100 | F22: AMD | G22: =ROUND(E22*환율!$B$5/1,0) | H22: ○ | I22: 또는 얀덱스 택시
A23: 9/28 | B23: 가르니 → 게하르트 왕복 | C23: 택시 | D23: 시내 | E23: 3000 | F23: AMD | G23: =ROUND(E23*환율!$B$5/1,0) | H23: ✕ | I23: 9km, 대중교통 없음 · 1인 단독이라 전액 부담
A24: 9/29 | B24: 예레반 → 에치미아진 왕복 | C24: 마르슈르트카 | D24: 시내 | E24: 600 | F24: AMD | G24: =ROUND(E24*환율!$B$5/1,0) | H24: ○ | I24: 킬리키아 터미널
A25: 9/29 | B25: 예레반 → 코르 비랍 왕복 | C25: 마르슈르트카 | D25: 시내 | E25: 1200 | F25: AMD | G25: =ROUND(E25*환율!$B$5/1,0) | H25: △ | I25: 하루 몇 편뿐
A26: 9/30 | B26: 예레반 → 아레니 갈림길 → 고리스 | C26: 마르슈르트카 | D26: 시외 | E26: 3000 | F26: AMD | G26: =ROUND(E26*환율!$B$5/1,0) | H26: ○ | I26: 노라방크 입구에서 하차 후 지나가는 차 재탑승
A27: 9/30 | B27: 아레니 갈림길 → 노라방크 왕복 | C27: 택시 | D27: 시내 | E27: 4000 | F27: AMD | G27: =ROUND(E27*환율!$B$5/1,0) | H27: ✕ | I27: 8km, 대중교통 없음 · 1인 단독이라 전액 부담
A28: 10/1 | B28: 고리스 → 할리조르 승강장 왕복 | C28: 택시 | D28: 시내 | E28: 6000 | F28: AMD | G28: =ROUND(E28*환율!$B$5/1,0) | H28: ✕ | I28: 타테브 케이블카 승강장 · 1인 단독이라 전액 부담
... A31: 10/3 | B31: 예레반 → 즈바르트노츠 공항 | C31: 택시 | D31: 시내 | E31: 4000 | F31: AMD | G31: =ROUND(E31*환율!$B$5/1,0) | H31: △ | I31: 01:30경 출발, 심야 할증 감안
A32: 10/3 | B32: 아테네 공항 → 신타그마역 | C32: 메트로 3호선 | D32: 시내 | E32: 10 | F32: EUR | G32: =ROUND(E32*환율!$B$6/1,0) | H32: ○ | I32: 공항선 정액 10유로, 40분
A33: 10/3 | B33: 아테네 시내 이동 | C33: 메트로·트램 4~5회 | D33: 시내 | E33: 6 | F33: EUR | G33: =ROUND(E33*환율!$B$6/1,0) | H33: ○ | I33: 1회 1.20유로. 대부분 도보권이라 보조 수단
A34: 10/4 | B34: 아테네 → 공항 (04:10 출발) | C34: X95 공항버스 | D34: 시내 | E34: 6.2 | F34: EUR | G34: =ROUND(E34*환율!$B$6/1,0) | H34: ○ | I34: 신타그마 발 24시간 운행 · 야간 60분 간격이라 03:55까지 정류장 도착 · 승차권은 전날 지하철역에서 미리 구입 · 택시는 심야 정액 55유로
A35: 10/4 | B35: 자이드 국제공항 → TRYP 호텔 | C35: 택시 | D35: 시내 | E35: 90 | F35: AED | G35: =ROUND(E35*환율!$B$7/1,0) | H35: ✕ | I35: 칼리파 bin 자이드 St · 30~40분 · 미터 약 85~100디르함
A36: 10/4 | B36: TRYP 호텔 → 루브르 아부다비 | C36: 택시 | D36: 시내 | E36: 45 | F36: AED | G36: =ROUND(E36*환율!$B$7/1,0) | H36: ✕ | I36: 사디야트 섬 · 약 14km, 20~25분
A37: 10/4 | B37: 루브르 → 셰이크 자이드 모스크 | C37: 택시 | D37: 시내 | E37: 75 | F37: AED | G37: =ROUND(E37*환율!$B$7/1,0) | H37: ✕ | I37: 섬 반대편 횡단 약 28km, 30~35분 · 94번 버스면 2디르함이나 60~75분
A38: 10/4 | B38: 모스크 → TRYP 호텔 | C38: 택시 | D38: 시내 | E38: 45 | F38: AED | G38: =ROUND(E38*환율!$B$7/1,0) | H38: ✕ | I38: 약 14km, 18~20분
A39: 10/5 | B39: TRYP 호텔 → 공항 (05:30) | C39: A2 공항버스 | D39: 시내 | E39: 14 | F39: AED | G39: =ROUND(E39*환율!$B$7/1,0) | H39: ○ | I39: 버스 4디르함 + 하필라트 카드 10디르함 · 칼리파 bin 자이드 St 승차 · 40~45분
A40: 9/28 | B40: 예레반 → 가르니 왕복 | C40: 266·284번 버스 | D40: 시외 | E40: 500 | F40: AMD | G40: =ROUND(E40*환율!$B$5/1,0) | H40: ○ | I40: 가이 정류장 출발 · 30분 간격 · 왕복 500드람
A41: 9/24 | B41: 스테판츠민다 → 주타 왕복 | C41: 4WD 택시 (대기 포함) | D41: 시내 | E41: 80 | F41: GEL | G41: =ROUND(E41*환율!$B$4/1,0) | H41: ✕ | I41: 대중교통 없음 · 25km 비포장 · 1인 단독이면 전액. 동행 구하면 40라리
A42: 9/25 | B42: 트빌리시 → 시그나기 왕복 | C42: 마르슈르트카 | D42: 시외 | E42: 25 | F42: GEL | G42: =ROUND(E42*환율!$B$4/1,0) | H42: ○ | I42: 삼고리 터미널 출발 · 편도 2~2.5시간 · 보드베는 요청하면 하차 · 돌아오는 막차 18~19시
A43: 교통비 합계 | G43: =SUM(G5:G42)
...

Sheet 입장료
A1: 입장료 — 수도원은 대부분 무료
A3: 날짜 | B3: 장소 | C3: 현지 금액 | D3: 통화 | E3: 원화 | F3: 비고
A4: 9/19 | B4: 예원 (豫园) | C4: 40 | D4: CNY | E4: =ROUND(C4*환율!$B$8,0) | F4: 09:00~16:30 폐장(매표 마감 더 이름) · 9월은 성수기 요금 40위안
A5: 9/21 | B5: 아바노투바니 유황온천 (공용탕) | C5: 5 | D5: GEL | E5: =ROUND(C5*환율!$B$4,0) | F5: 개인탕은 50~100라리
A6: 9/21 | B6: 나리칼라 케이블카 편도×2 | C6: 2 | D6: GEL | E6: =ROUND(C6*환율!$B$4,0) | F6: 메트로머니로 결제
A7: 9/22 | B7: 스베티츠호벨리 대성당 | C7: 0 | D7: GEL | E7: =ROUND(C7*환율!$B$4,0) | F7: 무료
A8: 9/22 | B8: 즈바리 수도원 | C8: 0 | D8: GEL | E8: =ROUND(C8*환율!$B$4,0) | F8: 무료
A9: 9/24 | B9: 게르게티 삼위일체 교회 | C9: 0 | D9: GEL | E9: =ROUND(C9*환율!$B$4,0) | F9: 무료
A10: 9/26 | B10: 사나힌 수도원 | C10: 0 | D10: AMD | E10: =ROUND(C10*환율!$B$5,0) | F10: 무료
A11: 9/25 | B11: 시그나기 와이너리 시음 (선택) | C11: 15 | D11: GEL | E11: =ROUND(C11*환율!$B$4,0) | F11: 크베브리 오렌지와인. 생략 가능 · 보드베·시그나기 성벽은 무료
A12: 9/26 | B12: 하흐파트 수도원 | C12: 0 | D12: AMD | E12: =ROUND(C12*환율!$B$5,0) | F12: 무료
A13: 10/2 | B13: 세바나방크 | C13: 0 | D13: AMD | E13: =ROUND(C13*환율!$B$5,0) | F13: 무료
A14: 9/28 | B14: 가르니 신전 | C14: 1800 | D14: AMD | E14: =ROUND(C14*환율!$B$5,0) | F14: 돌의 교향곡은 무료
A15: 9/28 | B15: 게하르트 수도원 | C15: 0 | D15: AMD | E15: =ROUND(C15*환율!$B$5,0) | F15: 무료
A16: 9/29 | B16: 에치미아진 보물관 | C16: 1500 | D16: AMD | E16: =ROUND(C16*환율!$B$5,0) | F16: 대성당 자체는 무료
A17: 9/29 | B17: 코르 비랍 | C17: 0 | D17: AMD | E17: =ROUND(C17*환율!$B$5,0) | F17: 무료
A18: 9/30 | B18: 노라방크 | C18: 0 | D18: AMD | E18: =ROUND(C18*환율!$B$5,0) | F18: 무료
A19: 10/1 | B19: 윙스 오브 타테브 케이블카 왕복 | C19: 8000 | D19: AMD | E19: =ROUND(C19*환율!$B$5,0) | F19: 월요일 휴무
A20: 10/1 | B20: 타테브 수도원 | C20: 0 | D20: AMD | E20: =ROUND(C20*환율!$B$5,0) | F20: 무료
A21: 10/3 | B21: 아크로폴리스 | C21: 30 | D21: EUR | E21: =ROUND(C21*환율!$B$6,0) | F21: hhticket.gr 공식 정가 30유로(연중 동일) · 타임드 엔트리 필수 · 60일 전 오픈, 성수기 5~7일 전 매진
A22: 10/3 | B22: 고대 아고라 · 헤파이스토스 신전 | C22: 12 | D22: EUR | E22: =ROUND(C22*환율!$B$6,0) | F22: 통합권 폐지로 별도 구매 필요 — 현장 확인
A23: 10/3 | B23: 아크로폴리스 박물관 | C23: 20 | D23: EUR | E23: =ROUND(C23*환율!$B$6,0) | F23: 실제 확인가 (별도 티켓)
A24: 10/4 | B24: 루브르 아부다비 | C24: 63 | D24: AED | E24: =ROUND(C24*환율!$B$7,0) | F24: 10/4 일요일 10:00~20:30, 최종 입장 20:00 · 월요일 휴관 · 돔은 자정까지
A25: 10/4 | B25: 셰이크 자이드 그랜드 모스크 | C25: 0 | D25: AED | E25: =ROUND(C25*환율!$B$7,0) | F25: 무료
B26: 입장료 합계 | E26: =SUM(E4:E25)
A28: 조지아·아르메니아 수도원은 대부분 무료입니다. 지출은 타테브 케이블카·아크로폴리스·루브르에 몰려 있습니다.

Sheet 일자별예산
A1: 일자별 예산 (1인 기준, 원)
A2: 1인 단독 여행 기준. 택시·기사 비용은 나눌 사람이 없어 전액 부담으로 계산했습니다. 9/19 상하이 1박은 항공권과 별개인 실제 지출이라 일정에 포함했습니다.
A4: 날짜 | B4: 요일 | C4: 숙박지 / 주요 일정 | D4: 관광·입장비 | E4: 식비 | F4: 숙박비 | G4: 카페 | H4: 시외교통 | I4: 시내교통 | J4: 일계 | K4: 누계
A5: 9/19 | B5: 토 | C5: 상하이 — 예원·성황묘·와이탄 야경 | D5: =SUMIF(입장료!$A$4:$A$25,A5,입장료!$E$4:$E$25) | E5: 25000 | F5: 28907 | G5: 6000 | H5: =SUMIFS(교통상세!$G$5:$G$42,교통상세!$A$5:$A$42,A5,교통상세!$D$5:$D$42,"시외") | I5: =SUMIFS(교통상세!$G$5:$G$42,교통상세!$A$5:$A$42,A5,교통상세!$D$5:$D$42,"시내") | J5: =SUM(D5:I5) | K5: =J5
A6: 9/20 | B6: 일 | C6: 상하이 오전 → 트빌리시 19:00 도착 | D6: =SUMIF(입장료!$A$4:$A$25,A6,입장료!$E$4:$E$25) | E6: 20000 | F6: 15689 | G6: 0 | H6: =SUMIFS(교통상세!$G$5:$G$42,교통상세!$A$5:$A$42,A6,교통상세!$D$5:$D$42,"시외") | I6: =SUMIFS(교통상세!$G$5:$G$42,교통상세!$A$5:$A$42,A6,교통상세!$D$5:$D$42,"시내") | J6: =SUM(D6:I6) | K6: =K5+J6
A7: 9/21 | B7: 월 | C7: 트빌리시 — 구시가·유황온천 | D7: =SUMIF(입장료!$A$4:$A$25,A7,입장료!$E$4:$E$25) | E7: 25000 | F7: 15689 | G7: 6000 | H7: =SUMIFS(교통상세!$G$5:$G$42,교통상세!$A$5:$A$42,A7,교통상세!$D$5:$D$42,"시외") | I7: =SUMIFS(교통상세!$G$5:$G$42,교통상세!$A$5:$A$42,A7,교통상세!$D$5:$D$42,"시내") | J7: =SUM(D7:I7) | K7: =K6+J7
A8: 9/22 | B8: 화 | C8: 트빌리시 — 므츠헤타 반나절 | D8: =SUMIF(입장료!$A$4:$A$25,A8,입장료!$E$4:$E$25) | E8: 25000 | F8: 15689 | G8: 6000 | H8: =SUMIFS(교통상세!$G$5:$G$42,교통상세!$A$5:$A$42,A8,교통상세!$D$5:$D$42,"시외") | I8: =SUMIFS(교통상세!$G$5:$G$42,교통상세!$A$5:$A$42,A8,교통상세!$D$5:$D$42,"시내") | J8: =SUM(D8:I8) | K8: =K7+J8
A9: 9/23 | B9: 수 | C9: 카즈베기 — 군사도로 · 게르게티 (1박) | D9: =SUMIF(입장료!$A$4:$A$25,A9,입장료!$E$4:$E$25) | E9: 25000 | F9: 28000 | G9: 5000 | H9: =SUMIFS(교통상세!$G$5:$G$42,교통상세!$A$5:$A$42,A9,교통상세!$D$5:$D$42,"시외") | I9: =SUMIFS(교통상세!$G$5:$G$42,교통상세!$A$5:$A$42,A9,교통상세!$D$5:$D$42,"시내") | J9: =SUM(D9:I9) | K9: =K8+J9
A10: 9/24 | B10: 목 | C10: 주타 데이 트레킹 → 트빌리시 복귀 | D10: =SUMIF(입장료!$A$4:$A$25,A10,입장료!$E$4:$E$25) | E10: 25000 | F10: 15689 | G10: 5000 | H10: =SUMIFS(교통상세!$G$5:$G$42,교통상세!$A$5:$A$42,A10,교통상세!$D$5:$D$42,"시외") | I10: =SUMIFS(교통상세!$G$5:$G$42,교통상세!$A$5:$A$42,A10,교통상세!$D$5:$D$42,"시내") | J10: =SUM(D10:I10) | K10: =K9+J10
A11: 9/25 | B11: 금 | C11: 시그나기 · 보드베 당일치기 (카헤티) | D11: =SUMIF(입장료!$A$4:$A$25,A11,입장료!$E$4:$E$25) | E11: 25000 | F11: 15689 | G11: 5000 | H11: =SUMIFS(교통상세!$G$5:$G$42,교통상세!$A$5:$A$42,A11,교통상세!$D$5:$D$42,"시외") | I11: =SUMIFS(교통상세!$G$5:$G$42,교통상세!$A$5:$A$42,A11,교통상세!$D$5:$D$42,"시내") | J11: =SUM(D11:I11) | K11: =K10+J11
A12: 9/26 | B12: 토 | C12: 알라베르디 — 하흐파트·사나힌 | D12: =SUMIF(입장료!$A$4:$A$25,A12,입장료!$E$4:$E$25) | E12: 25000 | F12: 25000 | G12: 5000 | H12: =SUMIFS(교통상세!$G$5:$G$42,교통상세!$A$5:$A$42,A12,교통상세!$D$5:$D$42,"시외") | I12: =SUMIFS(교통상세!$G$5:$G$42,교통상세!$A$5:$A$42,A12,교통상세!$D$5:$D$42,"시내") | J12: =SUM(D12:I12) | K12: =K11+J12
A13: 9/27 | B13: 일 | C13: 예레반 — 베르니사쥬·캐스케이드 | D13: =SUMIF(입장료!$A$4:$A$25,A13,입장료!$E$4:$E$25) | E13: 27000 | F13: 20000 | G13: 5000 | H13: =SUMIFS(교통상세!$G$5:$G$42,교통상세!$A$5:$A$42,A13,교통상세!$D$5:$D$42,"시외") | I13: =SUMIFS(교통상세!$G$5:$G$42,교통상세!$A$5:$A$42,A13,교통상세!$D$5:$D$42,"시내") | J13: =SUM(D13:I13) | K13: =K12+J13
A14: 9/28 | B14: 월 | C14: 예레반 — 가르니·게하르트 | D14: =SUMIF(입장료!$A$4:$A$25,A14,입장료!$E$4:$E$25) | E14: 30000 | F14: 20000 | G14: 6000 | H14: =SUMIFS(교통상세!$G$5:$G$42,교통상세!$A$5:$A$42,A14,교통상세!$D$5:$D$42,"시외") | I14: =SUMIFS(교통상세!$G$5:$G$42,교통상세!$A$5:$A$42,A14,교통상세!$D$5:$D$42,"시내") | J14: =SUM(D14:I14) | K14: =K13+J14
A15: 9/29 | B15: 화 | C15: 예레반 — 에치미아진·코르 비랍 | D15: =SUMIF(입장료!$A$4:$A$25,A15,입장료!$E$4:$E$25) | E15: 30000 | F15: 20000 | G15: 6000 | H15: =SUMIFS(교통상세!$G$5:$G$42,교통상세!$A$5:$A$42,A15,교통상세!$D$5:$D$42,"시외") | I15: =SUMIFS(교통상세!$G$5:$G$42,교통상세!$A$5:$A$42,A15,교통상세!$D$5:$D$42,"시내") | J15: =SUM(D15:I15) | K15: =K14+J15
A16: 9/30 | B16: 수 | C16: 고리스 — 노라방크 | D16: =SUMIF(입장료!$A$4:$A$25,A16,입장료!$E$4:$E$25) | E16: 30000 | F16: 25000 | G16: 5000 | H16: =SUMIFS(교통상세!$G$5:$G$42,교통상세!$A$5:$A$42,A16,교통상세!$D$5:$D$42,"시외") | I16: =SUMIFS(교통상세!$G$5:$G$42,교통상세!$A$5:$A$42,A16,교통상세!$D$5:$D$42,"시내") | J16: =SUM(D16:I16) | K16: =K15+J16
A17: 10/1 | B17: 목 | C17: 예레반 복귀 — 타테브 | D17: =SUMIF(입장료!$A$4:$A$25,A17,입장료!$E$4:$E$25) | E17: 30000 | F17: 20000 | G17: 5000 | H17: =SUMIFS(교통상세!$G$5:$G$42,교통상세!$A$5:$A$42,A17,교통상세!$D$5:$D$42,"시외") | I17: =SUMIFS(교통상세!$G$5:$G$42,교통상세!$A$5:$A$42,A17,교통상세!$D$5:$D$42,"시내") | J17: =SUM(D17:I17) | K17: =K16+J17
... A21: 10/5 | B21: 월 | C21: 아부다비 → 인천 (08:35 출발) · 새벽 A2 버스 | D21: =SUMIF(입장료!$A$4:$A$25,A21,입장료!$E$4:$E$25) | E21: 15000 | F21: 0 | G21: 0 | H21: =SUMIFS(교통상세!$G$5:$G$42,교통상세!$A$5:$A$42,A21,교통상세!$D$5:$D$42,"시외") | I21: =SUMIFS(교통상세!$G$5:$G$42,교통상세!$A$5:$A$42,A21,교통상세!$D$5:$D$42,"시내") | J21: =SUM(D21:I21) | K21: =K20+J21
A22: 합계 | D22: =SUM(D5:D21) | E22: =SUM(E5:E21) | F22: =SUM(F5:F21) | G22: =SUM(G5:G21) | H22: =SUM(H5:H21) | I22: =SUM(I5:I21) | J22: =SUM(J5:J21)
A24: 총예산 점검
A25: 현지 지출 합계 | B25: =J22
A26: 항공권 | B26: =환율!B13
A27: 소계 | B27: =B25+B26
A28: 총예산 (1인) | B28: =환율!B14
A29: 잔여 여유분 | B29: =B28-B27
A31: ※ 여행자보험·유심(중국은 로밍 권장 / 조지아·아르메니아·그리스·UAE 각각)·기념품·와인 구매 등은 별도 고려하세요.
A32: ※ 확정 숙소 — 상하이 Hi Cozy International Youth Hostel 137위안/1박(황푸구, 난징둥루역 도보권), 트빌리시 Cosy Koala Hostel 58라리/2박. 트빌리시는 9/22·9/25 두 밤이 추가로 필요합니다.
A33: ※ 미예약 숙소(카즈베기·알라베르디·딜리잔·예레반·고리스)는 도미토리 기준 추정치입니다. 개인실을 잡으면 1인 여행이라 이 금액의 두 배 가까이 올라갑니다.
A34: ※ 아테네 숙소는 30유로/1박 확정 — 신타그마 근처. 원래 잡아둔 90,000원에서 40,800원 줄었습니다. 08:00 짐 보관이 가능한 곳이어야 합니다(아크로폴리스 큰 가방 반입 불가).
A35: ※ 아부다비 숙소는 TRYP by Wyndham Abu Dhabi City Center(칼리파 bin 자이드 St) — 항공권 스톱오버에 포함되어 숙박비 0원. A2 공항버스가 이 도로에 정차합니다.
A36: ※ 9/24 주타는 대중교통이 없어 4WD 택시 왕복 80라리(1인 전액)입니다. 카즈베기 게스트하우스에서 동행을 구하면 40라리로 줄어듭니다.
