Workbook

Sheet 일정
A1: 일정 — 날짜별 코스
A2: 일정 YAML 에서 그대로 생성한 시트입니다. HTML 문서와 같은 소스라 숫자·시각이 갈라지지 않습니다. 「이동」이 비어 있으면 걸어서 가는 구간이고, 「주의」 행은 그 날이 무너질 수 있는 지점입니다. 4행에 필터가 걸려 있으니 날짜나 이동수단으로 걸러 보세요.
A4: 날짜 | B4: 요일 | C4: 구간 | D4: 시각 | E4: 이동 | F4: 내용 | G4: 비고
A5: 9/19 | B5: 토 | C5: 상하이 — 훙차오 12:55 도착 | F5: 경유가 아니라 반나절짜리 하루가 생겼습니다. 예원에서 와이탄까지 한 줄로 걷는 코스.
A6: 9/19 | B6: 토 | D6: 12:55 | F6: 훙차오 국제공항 T1 도착
A7: 9/19 | B7: 토 | D7: 13:35 | F7: 입국 수속 · 짐 수령 | G7: 별도 발권이라 짐은 여기서 한 번 찾습니다
A8: 9/19 | B8: 토 | D8: 13:50 | E8: 지하철 10호선 | F8: 난징둥루역 | G8: 5위안 · 45분 · T1역에서 바로 승차, 환승 없음
A9: 9/19 | B9: 토 | D9: 14:40 | F9: Hi Cozy 호스텔 체크인 — 짐만 두고 바로 출발 | G9: 난징둥루역 도보권. 옥상 공용 라운지가 좋다는 평
A10: 9/19 | B10: 토 | D10: 15:15 | E10: 10호선 한 정거장 | F10: 예원역 | G10: 또는 도보 20분
A11: 9/19 | B11: 토 | D11: 15:30 | F11: 예원 (豫园) | G11: [16:30 폐장] 40위안 · 명·청대 강남 정원. 좁은 회랑이 계속 꺾이며 풍경을 바꾸는 구조
A12: 9/19 | B12: 토 | D12: 16:40 | F12: 예원 라오제 — 난샹만터우뎬 샤오롱바오 | G12: 정원 담장 밖 상가. 1900년대 초부터 있던 원조 지점이 여기
A13: 9/19 | B13: 토 | D13: 17:10 | F13: 상하이 성황묘 | G13: 도교 사원. 해가 지면 붉은 조명이 들어와 낮과 완전히 다릅니다
A14: 9/19 | B14: 토 | D14: 17:40 | F14: 와이탄까지 도보 | G14: 15분. 옛 성곽 골목을 빠져나오면 갑자기 강변
A15: 9/19 | B15: 토 | D15: 17:50 | F15: 황푸강변 일몰 · 조계지 석조 건물 열
A16: 9/19 | B16: 토 | D16: 18:30 | F16: 푸동 스카이라인 야경 점등 | G16: 이 시간대가 상하이에서 가장 볼 만한 장면
A17: 9/19 | B17: 토 | D17: 19:15 | F17: 난징둥루 보행가로 걸어 돌아오며 저녁 | G17: 훙사오러우, 성젠바오. 보행가 큰길보다 한 블록 안쪽이 낫습니다
A18: 9/19 | B18: 토 | D18: 21:00 | F18: 숙소 복귀 · 취침 | G18: 36시간 이동의 중간 지점. 여기서 자두는 게 이번 일정의 핵심
A19: 9/19 | B19: 토 | D19: 07:30 | F19: 기상 · 조식 | G19: 날짜가 9/20으로 넘어갑니다
A20: 9/19 | B20: 토 | D20: 08:30 | F20: 체크아웃
A21: 9/19 | B21: 토 | D21: 08:50 | E21: 지하철 2호선 | F21: 푸동 국제공항 | G21: 8위안 · 1시간 15분 · 광란루역에서 열차를 갈아타야 함(같은 2호선이지만 운행이 끊김)
A22: 9/19 | B22: 토 | D22: 10:15 | F22: 푸동공항 도착 · 체크인 | G22: 12:50 출발 기준 2시간 35분 전
A23: 9/19 | B23: 토 | E23: 주의 | F23: 오늘 하루의 유일한 관문은 예원 16:30 폐장입니다. 매표 마감은 그보다 이르니 16시 전에는 들어가야 해요. 입국 심사가 밀려 15:30을 넘길 것 같으면 체크인을 건너뛰고 10호선으로 예원역까지 직행하세요(짐은 상가 물품보관함 또는 저녁에 숙소로). 그래도 못 들어가면 담장 밖 예원 라오제와 성황묘는 밤에 더 좋습니다 — 등롱 조명이 들어오면 정원 안보다 오히려 인상적이라는 평이 많아요.
A24: 9/19 | B24: 토 | E24: 주의 | F24: 알리페이 또는 위챗페이를 출발 전에 반드시 세팅하세요. 상하이는 노점·지하철·택시까지 QR 결제가 기본이고 해외 신용카드는 거부되는 곳이 많습니다. 두 앱 모두 해외 카드 연동이 되니 한국에서 미리 등록하고 소액 결제로 작동을 확인해두세요. 인터넷은 구글·카카오가 차단되니 한국 통신사 로밍을 켜두면 우회됩니다.
A25: 9/19 | B25: 토 | E25: 주의 | F25: 체력이 남으면 저녁 후 황푸강 야경 유람선(120위안, 40분)을, 조용한 쪽이 좋으면 신톈디(10호선 두 정거장)를 붙이세요. 반대로 지치면 예원을 버리고 와이탄 야경 하나만 봐도 충분합니다.
C26: ✈ 이동 | F26: 상하이 푸동 12:50 → 트빌리시 19:00 | G26: 시차 4시간 포함 총 소요 10시간 10분. 김포 출발부터 세면 36시간짜리 여정의 마지막 구간입니다. 상하이에서 한 번 잤기 때문에 도착일 컨디션은 나쁘지 않습니다.
A27: 9/20 | B27: 일 | C27: 트빌리시 도착 | F27: 36시간 이동의 끝. 오늘은 숙소까지 가는 것이 전부.
A28: 9/20 | B28: 일 | D28: 19:00 | F28: 트빌리시 국제공항 도착
A29: 9/20 | B29: 일 | D29: 20:00 | F29: 입국 수속 · 공항 ATM에서 라리 인출 | G29: 공항 환전소는 환율이 나쁨. ATM 쪽이 유리
A30: 9/20 | B30: 일 | D30: 20:30 | E30: 37번 버스 | F30: 시내로 | G30: 1라리 · 40분 · 24시간 운행
A31: 9/20 | B31: 일 | D31: 21:30 | F31: 숙소 체크인
A32: 9/20 | B32: 일 | D32: 22:00 | F32: 근처에서 늦은 저녁
A33: 9/21 | B33: 월 | C33: 트빌리시 구시가 — 월요일 · 야외만 | F33: 월요일이라 박물관은 대부분 닫습니다. 그래서 오늘은 능선의 요새와 유황온천 골목만 걷습니다.
A34: 9/21 | B34: 월 | D34: 09:00 | F34: 늦은 조식 · 자유광장 방향으로
A35: 9/21 | B35: 월 | D35: 09:30 | F35: 시오니 대성당 | G35: 무료 · 조지아 정교회의 옛 총본산. 성 니노의 포도나무 십자가가 있습니다
A36: 9/21 | B36: 월 | D36: 10:00 | F36: 평화의 다리 · 리케 공원
A37: 9/21 | B37: 월 | D37: 10:30 | E37: 케이블카 | F37: 리케 공원 케이블카로 능선까지 | G37: 편도 2.5라리 · 메트로머니 카드로 탑승 · 3분
A38: 9/21 | B38: 월 | D38: 11:00 | F38: 나리칼라 요새 | G38: [무료] 4세기 성채. 구시가와 므트크바리 강이 통째로 내려다보입니다
A39: 9/21 | B39: 월 | D39: 12:00 | F39: 능선길을 따라 조지아의 어머니 상까지 도보
A40: 9/21 | B40: 월 | D40: 13:00 | F40: 구시가 점심
A41: 9/21 | B41: 월 | D41: 14:30 | F41: 아바노투바니 유황온천 | G41: 공동탕 5~10라리 · 개인탕 1시간 40~70라리. 벽돌 돔이 늘어선 골목 자체가 볼거리
...

Sheet 환율
A1: 환율 및 기본 가정
A3: 항목 | B3: 값 | C3: 비고
A4: 조지아 라리 (GEL) → 원 | B4: 541 | C4: 2026년 8월 6일 조지아·아르메니아 중앙은행 공시 기준 (USD/KRW 1,420 교차 산출)
A5: 아르메니아 드람 (AMD) → 원 | B5: 3.88 | C5: 2026년 8월 6일 조지아·아르메니아 중앙은행 공시 기준 (USD/KRW 1,420 교차 산출)
A6: 유로 (EUR) → 원 | B6: 1640 | C6: 2026년 8월 6일 시장환율 — 아테네 구간
A7: UAE 디르함 (AED) → 원 | B7: 387 | C7: 2026년 8월 6일 시장환율 (USD 페그 3.6725) — 아부다비 구간
A8: 중국 위안 (CNY) → 원 | B8: 211 | C8: 2026년 8월 6일 시장환율 — 상하이 경유 구간
A9: 인원 | B9: 1 | C9: 1인 여행 — 지프·택시 비용을 나눌 사람이 없어 전액 부담
A10: 항공권1 — 김포→상하이 + 푸동→트빌리시 (별도 발권 2편) | B10: 446000
A11: 항공권2 — 예레반→아테네 (에게안 A3 3899 · XD9TVH) | B11: 303900
A12: 항공권3 — 아테네→아부다비→인천 (아부다비 1박 포함) | B12: 656700
A13: 항공권 합계 | B13: =SUM(B10:B12) | C13: 3편 모두 결제 완료. 이후 환율 변동은 현지 지출에만 영향
A14: 총예산 (1인) | B14: 3000000 | C14: 사용자 제시: 300만원
A16: 노란 셀만 수정하세요. 나머지 시트는 이 값을 참조해 자동 계산됩니다.
A17: 환율은 현지 지출에만 적용됩니다 (항공권은 결제 완료로 원화 확정). 전 통화 2026년 8월 6일 기준 — 출발 직전에 한 번 더 갱신하세요.
A18: 여행 직전 실제 환율로 한 번 더 갱신하는 것을 권장합니다 — 환율은 매일 바뀝니다.

Sheet 교통상세
A1: 구간별 교통 — 대중교통 우선
A2: ‘대중교통’ 열이 ○ 이면 마르슈르트카·버스·지하철로 갈 수 있는 구간, △ 는 부분적, ✕ 는 택시가 사실상 필수인 구간입니다. 택시 요금은 환율 시트의 인원(현재 1명)으로 나눈 1인 부담액입니다.
A4: 날짜 | B4: 구간 | C4: 수단 | D4: 구분 | E4: 현지 금액 | F4: 통화 | G4: 1인 원화 | H4: 대중교통 | I4: 비고
A5: 9/19 | B5: 훙차오 공항 T1 → 난징둥루 | C5: 지하철 10호선 | D5: 시내 | E5: 5 | F5: CNY | G5: =ROUND(E5*환율!$B$8/1,0) | H5: ○ | I5: 환승 없이 직통, 약 45분
A6: 9/19 | B6: 상하이 시내 이동 (예원·와이탄) | C6: 지하철 10호선 · 도보 | D6: 시내 | E6: 8 | F6: CNY | G6: =ROUND(E6*환율!$B$8/1,0) | H6: ○ | I6: 1회 3~4위안. 대부분 도보권
A7: 9/20 | B7: 시내 → 푸동 국제공항 | C7: 지하철 2호선 | D7: 시내 | E7: 8 | F7: CNY | G7: =ROUND(E7*환율!$B$8/1,0) | H7: ○ | I7: 광란루역에서 열차 갈아탐, 1시간 15분
A8: 9/20 | B8: 공항 → 트빌리시 시내 | C8: 버스 37번 | D8: 시내 | E8: 1 | F8: GEL | G8: =ROUND(E8*환율!$B$4/1,0) | H8: ○ | I8: 24시간 운행
A9: 9/21 | B9: 트빌리시 시내 | C9: 지하철·버스 (메트로머니) | D9: 시내 | E9: 4 | F9: GEL | G9: =ROUND(E9*환율!$B$4/1,0) | H9: ○ | I9: 하루 이동분
A10: 9/21 | B10: 리케 공원 → 나리칼라 케이블카 | C10: 케이블카 (편도) | D10: 시내 | E10: 2.5 | F10: GEL | G10: =ROUND(E10*환율!$B$4/1,0) | H10: ○ | I10: 메트로머니로 결제
A11: 9/22 | B11: 디두베 → 므츠헤타 왕복 | C11: 마르슈르트카 | D11: 시외 | E11: 3 | F11: GEL | G11: =ROUND(E11*환율!$B$4/1,0) | H11: ○ | I11: 편도 1.5라리 · 수시 운행
A12: 9/22 | B12: 므츠헤타 → 즈바리 수도원 왕복 | C12: 택시 (대기 포함) | D12: 시내 | E12: 25 | F12: GEL | G12: =ROUND(E12*환율!$B$4/1,0) | H12: ✕ | I12: 대중교통 없음 · 흥정
A13: 9/22 | B13: 트빌리시 시내 (국립박물관·벼룩시장) | C13: 지하철·도보 | D13: 시내 | E13: 2 | F13: GEL | G13: =ROUND(E13*환율!$B$4/1,0) | H13: ○
A14: 9/22 | B14: 시내 → 오르타찰라 터미널 (심야) | C14: 택시 | D14: 시내 | E14: 12 | F14: GEL | G14: =ROUND(E14*환율!$B$4/1,0) | H14: △ | I14: 지하철이 닿지 않음 · 볼트 앱
A15: 9/22 | B15: 트빌리시 → 주그디디 | C15: 야간버스 (OmniBus) | D15: 시외 | E15: 35 | F15: GEL | G15: =ROUND(E15*환율!$B$4/1,0) | H15: ○ | I15: 오르타찰라 23:45 발 · 05:30 주그디디역 도착 · 디두베 23:59 발도 있음 · 운행 여부를 출발 전 확인
A16: 9/23 | B16: 주그디디 → 메스티아 | C16: 마르슈르트카 (B안) · 합승택시 (A안) | D16: 시외 | E16: 40 | F16: GEL | G16: =ROUND(E16*환율!$B$4/1,0) | H16: ○ | I16: B안 기준 · 10:00 전후 발 · 3~4시간 · A안 합승택시는 넷이 나누면 1인 70~75라리
A17: 9/23 | B17: 메스티아 → 자베시 (B안) | C17: 택시 | D17: 시외 | E17: 50 | F17: GEL | G17: =ROUND(E17*환율!$B$4/1,0) | H17: ✕ | I17: 1일차 찻길 구간을 건너뜀 · 요금 자료가 적어 흥정 · A안(걸어서)이면 0
A18: 9/25 | B18: 아디시 강 건너기 | C18: 말 | D18: 시외 | E18: 25 | F18: GEL | G18: =ROUND(E18*환율!$B$4/1,0) | H18: ✕ | I18: 다리 없음 · 20~30라리 · 전날 게스트하우스에서 말꾼 확인
A19: 9/26 | B19: 우쉬굴리 → 메스티아 | C19: 공유 밴 | D19: 시외 | E19: 40 | F19: GEL | G19: =ROUND(E19*환율!$B$4/1,0) | H19: △ | I19: 넷이 차면 출발 · 1시간 반 안팎 · 정해진 시각 없음
A20: 9/26 | B20: 메스티아 → 주그디디 | C20: 마르슈르트카 | D20: 시외 | E20: 35 | F20: GEL | G20: =ROUND(E20*환율!$B$4/1,0) | H20: ○ | I20: 확실한 정기편은 08:00 · 오후 편은 9/23 에 확인 · 없으면 택시 차 한 대 약 300라리
A21: 9/26 | B21: 주그디디 → 트빌리시 | C21: 야간버스 (OmniBus) | D21: 시외 | E21: 35 | F21: GEL | G21: =ROUND(E21*환율!$B$4/1,0) | H21: ○ | I21: 주그디디역 23:59 발 · 05:20 오르타찰라 도착
A22: 9/27 | B22: 오르타찰라 → 디두베 터미널 | C22: 택시 | D22: 시내 | E22: 10 | F22: GEL | G22: =ROUND(E22*환율!$B$4/1,0) | H22: △ | I22: 지하철 첫차 전이라 택시
A23: 9/27 | B23: 디두베 → 스테판츠민다 | C23: 마르슈르트카 | D23: 시외 | E23: 15 | F23: GEL | G23: =ROUND(E23*환율!$B$4/1,0) | H23: ○ | I23: 3시간 반~4시간
A24: 9/27 | B24: 스테판츠민다 → 게르게티 교회 | C24: 4WD (편도) · 하산은 도보 | D24: 시내 | E24: 25 | F24: GEL | G24: =ROUND(E24*환율!$B$4/1,0) | H24: ✕ | I24: 오르막 400m
A25: 9/28 | B25: 스테판츠민다 → 트빌리시 | C25: 마르슈르트카 | D25: 시외 | E25: 15 | F25: GEL | G25: =ROUND(E25*환율!$B$4/1,0) | H25: ○ | I25: 13:30 편
A26: 9/28 | B26: 디두베 → 시내 | C26: 지하철 | D26: 시내 | E26: 1 | F26: GEL | G26: =ROUND(E26*환율!$B$4/1,0) | H26: ○
A27: 9/29 | B27: 시내 → 오르타찰라 터미널 | C27: 지하철·도보 | D27: 시내 | E27: 1 | F27: GEL | G27: =ROUND(E27*환율!$B$4/1,0) | H27: ○
A28: 9/29 | B28: 오르타찰라 → 알라베르디 | C28: 합승택시 (예레반행) | D28: 시외 | E28: 40 | F28: GEL | G28: =ROUND(E28*환율!$B$4/1,0) | H28: ○ | I28: 국경 통과 포함 · 알라베르디 하차를 미리 요청
A29: 9/29 | B29: 알라베르디 → 사나힌 · 하흐파트 → 알라베르디 | C29: 택시 한 대 (대기 포함) | D29: 시내 | E29: 6000 | F29: AMD | G29: =ROUND(E29*환율!$B$5/1,0) | H29: ○ | I29: 버스 네 번(왕복 800드람) 대신 · 1인 전액 부담
A30: 9/30 | B30: 알라베르디 → 예레반 | C30: 마르슈르트카 (바나조르 경유 또는 직행) | D30: 시외 | E30: 2500 | F30: AMD | G30: =ROUND(E30*환율!$B$5/1,0) | H30: ○ | I30: 4시간 안팎 · 지나가는 직행이 있으면 그걸 탑니다
A31: 9/30 | B31: 킬리키아 터미널 ↔ 숙소 | C31: 버스 · GG 택시 | D31: 시내 | E31: 600 | F31: AMD | G31: =ROUND(E31*환율!$B$5/1,0) | H31: ○ | I31: 도착 · 오후 출발 · 저녁 복귀 3회
A32: 9/30 | B32: 예레반 → 즈바르트노츠 | C32: 마르슈르트카 203·204번 | D32: 시외 | E32: 250 | F32: AMD | G32: =ROUND(E32*환율!$B$5/1,0) | H32: ○ | I32: 킬리키아 발 · 즈바르트노츠 하차 요청
A33: 9/30 | B33: 즈바르트노츠 → 에치미아진 | C33: 택시 또는 같은 버스 | D33: 시내 | E33: 1000 | F33: AMD | G33: =ROUND(E33*환율!$B$5/1,0) | H33: ○ | I33: 서쪽 4km · 버스를 다시 타면 0에 가깝습니다
A34: 9/30 | B34: 에치미아진 → 예레반 | C34: 마르슈르트카 | D34: 시외 | E34: 250 | F34: AMD | G34: =ROUND(E34*환율!$B$5/1,0) | H34: ○ | I34: 킬리키아 터미널행
A35: 10/1 | B35: 시내 ↔ 가이 정류장 | C35: 63번 버스 | D35: 시내 | E35: 200 | F35: AMD | G35: =ROUND(E35*환율!$B$5/1,0) | H35: ○ | I35: 왕복 · 편도 100드람 · 30분
A36: 10/1 | B36: 가이 정류장 ↔ 고흐트 · 가르니 | C36: 266·284번 버스 | D36: 시외 | E36: 500 | F36: AMD | G36: =ROUND(E36*환율!$B$5/1,0) | H36: ○ | I36: 편도 250드람 · 종점은 고흐트 · 편수는 자료마다 다름
A37: 10/1 | B37: 고흐트 → 게하르트 → 가르니 | C37: 택시 (대기 포함) | D37: 시내 | E37: 3000 | F37: AMD | G37: =ROUND(E37*환율!$B$5/1,0) | H37: ✕ | I37: 게하르트 구간은 대중교통 없음 · 1인 전액 부담
A38: 10/2 | B38: 예레반 ↔ 호르 비랍 | C38: 택시 왕복 (대기 포함) | D38: 시외 | E38: 12000 | F38: AMD | G38: =ROUND(E38*환율!$B$5/1,0) | H38: △ | I38: 12,000~15,000드람 · GG 왕복 협상 시 10,000 선 · 아르메니아 구간 최대 지출
A39: 10/2 | B39: 예레반 시내 (GUM → 추모관 → 파라자노프) | C39: GG 택시 2회 | D39: 시내 | E39: 2000 | F39: AMD | G39: =ROUND(E39*환율!$B$5/1,0) | H39: ○ | I39: 회당 600~1,500드람 · 파라자노프에서 숙소까지는 걸어갑니다
A40: 10/3 | B40: 예레반 → 즈바르트노츠 공항 | C40: 택시 (GG 앱) | D40: 시내 | E40: 4000 | F40: AMD | G40: =ROUND(E40*환율!$B$5/1,0) | H40: △ | I40: 01:30경 출발 · GG 앱으로 새벽에도 잡힙니다 · 심야 할증 감안
A41: 10/3 | B41: 아테네 공항 → 신타그마역 | C41: 메트로 3호선 | D41: 시내 | E41: 10 | F41: EUR | G41: =ROUND(E41*환율!$B$6/1,0) | H41: ○ | I41: 공항선 정액 10유로, 40분
...

Sheet 입장료
A1: 입장료 — 수도원은 대부분 무료
A3: 날짜 | B3: 장소 | C3: 현지 금액 | D3: 통화 | E3: 원화 | F3: 비고
A4: 9/19 | B4: 예원 (豫园) | C4: 40 | D4: CNY | E4: =ROUND(C4*환율!$B$8,0) | F4: 09:00~16:30 폐장(매표 마감 더 이름) · 9월은 성수기 요금 40위안
A5: 9/21 | B5: 아바노투바니 유황온천 (공용탕) | C5: 5 | D5: GEL | E5: =ROUND(C5*환율!$B$4,0) | F5: 공용탕 기준 · 개인실은 더 비쌈
A6: 9/21 | B6: 나리칼라 요새 | C6: 0 | D6: GEL | E6: =ROUND(C6*환율!$B$4,0) | F6: 무료 · 상시 개방
A7: 9/22 | B7: 스베티츠호벨리 대성당 | C7: 0 | D7: GEL | E7: =ROUND(C7*환율!$B$4,0) | F7: 무료 · 어깨·무릎을 가려야 함
A8: 9/22 | B8: 즈바리 수도원 | C8: 0 | D8: GEL | E8: =ROUND(C8*환율!$B$4,0) | F8: 무료
A9: 9/22 | B9: 조지아 국립박물관 | C9: 15 | D9: GEL | E9: =ROUND(C9*환율!$B$4,0) | F9: 월요일 휴관 — 화요일이라 엽니다
A10: 9/26 | B10: 우쉬굴리 차즈하시 입구 | C10: 2 | D10: GEL | E10: =ROUND(C10*환율!$B$4,0) | F10: 마을 입구에서 받는다는 기록(caucasus-trekking, 2026년 1월) · 현장 확인
A11: 9/26 | B11: 라마리아 교회 (우쉬굴리) | C11: 0 | D11: GEL | E11: =ROUND(C11*환율!$B$4,0) | F11: 무료 · 마을 위 언덕
A12: 9/27 | B12: 게르게티 삼위일체 교회 | C12: 0 | D12: GEL | E12: =ROUND(C12*환율!$B$4,0) | F12: 무료 · 어깨·무릎을 가려야 함
A13: 9/29 | B13: 사나힌 수도원 | C13: 0 | D13: AMD | E13: =ROUND(C13*환율!$B$5,0) | F13: 무료 · 유네스코 세계유산
A14: 9/29 | B14: 하흐파트 수도원 | C14: 0 | D14: AMD | E14: =ROUND(C14*환율!$B$5,0) | F14: 무료 · 유네스코 세계유산
A15: 9/29 | B15: 사나힌 다리 | C15: 0 | D15: AMD | E15: =ROUND(C15*환율!$B$5,0) | F15: 무료 · 12세기 아치교, 알라베르디 시내
A16: 9/30 | B16: 즈바르트노츠 유적 | C16: 1500 | D16: AMD | E16: =ROUND(C16*환율!$B$5,0) | F16: 공식 안내 매일 10:00~18:00(일 16:00) · 부속 박물관 포함
A17: 9/30 | B17: 에치미아진 대성당 | C17: 0 | D17: AMD | E17: =ROUND(C17*환율!$B$5,0) | F17: 무료 · 2024년 9월 29일 재개장
A18: 9/30 | B18: 성 흐립시메 교회 · 성 가야네 교회 | C18: 0 | D18: AMD | E18: =ROUND(C18*환율!$B$5,0) | F18: 무료
A19: 10/1 | B19: 게하르트 수도원 | C19: 0 | D19: AMD | E19: =ROUND(C19*환율!$B$5,0) | F19: 무료 · 유네스코 세계유산
A20: 10/1 | B20: 가르니 신전 | C20: 1800 | D20: AMD | E20: =ROUND(C20*환율!$B$5,0) | F20: 돌의 교향곡(협곡)은 무료
A21: 10/2 | B21: 호르 비랍 수도원 | C21: 0 | D21: AMD | E21: =ROUND(C21*환율!$B$5,0) | F21: 무료
A22: 10/2 | B22: 대학살 추모관 박물관 | C22: 0 | D22: AMD | E22: =ROUND(C22*환율!$B$5,0) | F22: 무료 · 3~12월 10:00~17:00, 16:30 입장 마감 · 월 휴관
A23: 10/2 | B23: 세르게이 파라자노프 박물관 | C23: 1000 | D23: AMD | E23: =ROUND(C23*환율!$B$5,0) | F23: 매일 10:30~17:00
A24: 10/3 | B24: 아크로폴리스 | C24: 30 | D24: EUR | E24: =ROUND(C24*환율!$B$6,0) | F24: hhticket.gr 공식 정가 30유로(연중 동일) · 타임드 엔트리 필수 · 60일 전 오픈, 성수기 5~7일 전 매진
A25: 10/3 | B25: 고대 아고라 · 헤파이스토스 신전 | C25: 12 | D25: EUR | E25: =ROUND(C25*환율!$B$6,0) | F25: 통합권 폐지로 별도 구매 필요 — 현장 확인
A26: 10/3 | B26: 아크로폴리스 박물관 | C26: 20 | D26: EUR | E26: =ROUND(C26*환율!$B$6,0) | F26: 실제 확인가 (별도 티켓)
A27: 10/4 | B27: 루브르 아부다비 | C27: 63 | D27: AED | E27: =ROUND(C27*환율!$B$7,0) | F27: 10/4 일요일 10:00~20:30, 최종 입장 20:00 · 월요일 휴관 · 돔은 자정까지
A28: 10/4 | B28: 셰이크 자이드 그랜드 모스크 | C28: 0 | D28: AED | E28: =ROUND(C28*환율!$B$7,0) | F28: 무료
B29: 입장료 합계 | E29: =SUM(E4:E28)
A31: 무료인 곳도 0으로 적어 빠뜨린 데가 없는지 볼 수 있게 했습니다. 하흐파트·사나힌·게하르트는 유네스코 세계유산인데 입장료가 없습니다(기부함만 있습니다).

Sheet 일자별예산
A1: 일자별 예산 (1인 기준, 원)
A2: 1인 단독 여행 기준. 택시·기사 비용은 나눌 사람이 없어 전액 부담으로 계산했습니다. 9/19 상하이 1박은 항공권과 별개인 실제 지출이라 일정에 포함했습니다.
A4: 날짜 | B4: 요일 | C4: 숙박지 / 주요 일정 | D4: 관광·입장비 | E4: 식비 | F4: 숙박비 | G4: 카페 | H4: 시외교통 | I4: 시내교통 | J4: 일계 | K4: 누계
A5: 9/19 | B5: 토 | C5: 상하이 — 예원·성황묘·와이탄 야경 | D5: =SUMIF(입장료!$A$4:$A$28,A5,입장료!$E$4:$E$28) | E5: 25000 | F5: 28907 | G5: 6000 | H5: =SUMIFS(교통상세!$G$5:$G$48,교통상세!$A$5:$A$48,A5,교통상세!$D$5:$D$48,"시외") | I5: =SUMIFS(교통상세!$G$5:$G$48,교통상세!$A$5:$A$48,A5,교통상세!$D$5:$D$48,"시내") | J5: =SUM(D5:I5) | K5: =J5
A6: 9/20 | B6: 일 | C6: 상하이 오전 → 트빌리시 19:00 도착 | D6: =SUMIF(입장료!$A$4:$A$28,A6,입장료!$E$4:$E$28) | E6: 20000 | F6: 15689 | G6: 0 | H6: =SUMIFS(교통상세!$G$5:$G$48,교통상세!$A$5:$A$48,A6,교통상세!$D$5:$D$48,"시외") | I6: =SUMIFS(교통상세!$G$5:$G$48,교통상세!$A$5:$A$48,A6,교통상세!$D$5:$D$48,"시내") | J6: =SUM(D6:I6) | K6: =K5+J6
A7: 9/21 | B7: 월 | C7: 트빌리시 — 구시가·나리칼라·유황온천 (월요일 휴관 회피) | D7: =SUMIF(입장료!$A$4:$A$28,A7,입장료!$E$4:$E$28) | E7: 25000 | F7: 15689 | G7: 6000 | H7: =SUMIFS(교통상세!$G$5:$G$48,교통상세!$A$5:$A$48,A7,교통상세!$D$5:$D$48,"시외") | I7: =SUMIFS(교통상세!$G$5:$G$48,교통상세!$A$5:$A$48,A7,교통상세!$D$5:$D$48,"시내") | J7: =SUM(D7:I7) | K7: =K6+J7
A8: 9/22 | B8: 화 | C8: 트빌리시 — 므츠헤타 반나절 · 밤 야간버스로 주그디디 | D8: =SUMIF(입장료!$A$4:$A$28,A8,입장료!$E$4:$E$28) | E8: 25000 | F8: 0 | G8: 6000 | H8: =SUMIFS(교통상세!$G$5:$G$48,교통상세!$A$5:$A$48,A8,교통상세!$D$5:$D$48,"시외") | I8: =SUMIFS(교통상세!$G$5:$G$48,교통상세!$A$5:$A$48,A8,교통상세!$D$5:$D$48,"시내") | J8: =SUM(D8:I8) | K8: =K7+J8
A9: 9/23 | B9: 수 | C9: 주그디디 → 메스티아 → 자베시 (트레킹 1일차) | D9: =SUMIF(입장료!$A$4:$A$28,A9,입장료!$E$4:$E$28) | E9: 20000 | F9: 45985 | G9: 5000 | H9: =SUMIFS(교통상세!$G$5:$G$48,교통상세!$A$5:$A$48,A9,교통상세!$D$5:$D$48,"시외") | I9: =SUMIFS(교통상세!$G$5:$G$48,교통상세!$A$5:$A$48,A9,교통상세!$D$5:$D$48,"시내") | J9: =SUM(D9:I9) | K9: =K8+J9
A10: 9/24 | B10: 목 | C10: 자베시 → 아디시 (트레킹 2일차) | D10: =SUMIF(입장료!$A$4:$A$28,A10,입장료!$E$4:$E$28) | E10: 15000 | F10: 45985 | G10: 0 | H10: =SUMIFS(교통상세!$G$5:$G$48,교통상세!$A$5:$A$48,A10,교통상세!$D$5:$D$48,"시외") | I10: =SUMIFS(교통상세!$G$5:$G$48,교통상세!$A$5:$A$48,A10,교통상세!$D$5:$D$48,"시내") | J10: =SUM(D10:I10) | K10: =K9+J10
A11: 9/25 | B11: 금 | C11: 아디시 → 치훈데리 고개 → 이프랄리 (3일차 · 말로 강 건너기) | D11: =SUMIF(입장료!$A$4:$A$28,A11,입장료!$E$4:$E$28) | E11: 15000 | F11: 45985 | G11: 0 | H11: =SUMIFS(교통상세!$G$5:$G$48,교통상세!$A$5:$A$48,A11,교통상세!$D$5:$D$48,"시외") | I11: =SUMIFS(교통상세!$G$5:$G$48,교통상세!$A$5:$A$48,A11,교통상세!$D$5:$D$48,"시내") | J11: =SUM(D11:I11) | K11: =K10+J11
A12: 9/26 | B12: 토 | C12: 이프랄리 → 우쉬굴리 (종주 끝) → 메스티아 → 주그디디 · 밤 야간버스로 트빌리시 | D12: =SUMIF(입장료!$A$4:$A$28,A12,입장료!$E$4:$E$28) | E12: 25000 | F12: 0 | G12: 5000 | H12: =SUMIFS(교통상세!$G$5:$G$48,교통상세!$A$5:$A$48,A12,교통상세!$D$5:$D$48,"시외") | I12: =SUMIFS(교통상세!$G$5:$G$48,교통상세!$A$5:$A$48,A12,교통상세!$D$5:$D$48,"시내") | J12: =SUM(D12:I12) | K12: =K11+J12
A13: 9/27 | B13: 일 | C13: 카즈베기 — 군사도로 · 게르게티 1차 (1박) | D13: =SUMIF(입장료!$A$4:$A$28,A13,입장료!$E$4:$E$28) | E13: 25000 | F13: 28000 | G13: 5000 | H13: =SUMIFS(교통상세!$G$5:$G$48,교통상세!$A$5:$A$48,A13,교통상세!$D$5:$D$48,"시외") | I13: =SUMIFS(교통상세!$G$5:$G$48,교통상세!$A$5:$A$48,A13,교통상세!$D$5:$D$48,"시내") | J13: =SUM(D13:I13) | K13: =K12+J13
A14: 9/28 | B14: 월 | C14: 카즈베기 오전 예비(게르게티 2차·마지막) → 트빌리시 복귀 | D14: =SUMIF(입장료!$A$4:$A$28,A14,입장료!$E$4:$E$28) | E14: 25000 | F14: 15689 | G14: 5000 | H14: =SUMIFS(교통상세!$G$5:$G$48,교통상세!$A$5:$A$48,A14,교통상세!$D$5:$D$48,"시외") | I14: =SUMIFS(교통상세!$G$5:$G$48,교통상세!$A$5:$A$48,A14,교통상세!$D$5:$D$48,"시내") | J14: =SUM(D14:I14) | K14: =K13+J14
A15: 9/29 | B15: 화 | C15: 국경 → 알라베르디 · 사나힌·하흐파트 (택시 한 대) · 사나힌 다리 | D15: =SUMIF(입장료!$A$4:$A$28,A15,입장료!$E$4:$E$28) | E15: 25000 | F15: 25000 | G15: 5000 | H15: =SUMIFS(교통상세!$G$5:$G$48,교통상세!$A$5:$A$48,A15,교통상세!$D$5:$D$48,"시외") | I15: =SUMIFS(교통상세!$G$5:$G$48,교통상세!$A$5:$A$48,A15,교통상세!$D$5:$D$48,"시내") | J15: =SUM(D15:I15) | K15: =K14+J15
A16: 9/30 | B16: 수 | C16: 알라베르디 → 예레반 · 즈바르트노츠·에치미아진 (3박 시작) | D16: =SUMIF(입장료!$A$4:$A$28,A16,입장료!$E$4:$E$28) | E16: 28000 | F16: 20000 | G16: 6000 | H16: =SUMIFS(교통상세!$G$5:$G$48,교통상세!$A$5:$A$48,A16,교통상세!$D$5:$D$48,"시외") | I16: =SUMIFS(교통상세!$G$5:$G$48,교통상세!$A$5:$A$48,A16,교통상세!$D$5:$D$48,"시내") | J16: =SUM(D16:I16) | K16: =K15+J16
A17: 10/1 | B17: 목 | C17: 예레반 — 게하르트 → 가르니 → 협곡 주상절리 (순서 역전) | D17: =SUMIF(입장료!$A$4:$A$28,A17,입장료!$E$4:$E$28) | E17: 30000 | F17: 20000 | G17: 6000 | H17: =SUMIFS(교통상세!$G$5:$G$48,교통상세!$A$5:$A$48,A17,교통상세!$D$5:$D$48,"시외") | I17: =SUMIFS(교통상세!$G$5:$G$48,교통상세!$A$5:$A$48,A17,교통상세!$D$5:$D$48,"시내") | J17: =SUM(D17:I17) | K17: =K16+J17
... A21: 10/5 | B21: 월 | C21: 아부다비 → 인천 (08:35 출발) · 새벽 A2 버스 | D21: =SUMIF(입장료!$A$4:$A$28,A21,입장료!$E$4:$E$28) | E21: 15000 | F21: 0 | G21: 0 | H21: =SUMIFS(교통상세!$G$5:$G$48,교통상세!$A$5:$A$48,A21,교통상세!$D$5:$D$48,"시외") | I21: =SUMIFS(교통상세!$G$5:$G$48,교통상세!$A$5:$A$48,A21,교통상세!$D$5:$D$48,"시내") | J21: =SUM(D21:I21) | K21: =K20+J21
A22: 합계 | D22: =SUM(D5:D21) | E22: =SUM(E5:E21) | F22: =SUM(F5:F21) | G22: =SUM(G5:G21) | H22: =SUM(H5:H21) | I22: =SUM(I5:I21) | J22: =SUM(J5:J21)
A24: 총예산 점검
A25: 현지 지출 합계 | B25: =J22
A26: 항공권 | B26: =환율!B13
A27: 소계 | B27: =B25+B26
A28: 총예산 (1인) | B28: =환율!B14
A29: 잔여 여유분 | B29: =B28-B27
A31: 야간버스 2회로 숙박 2박이 빠졌습니다(9/22·9/26 숙박비 0원). 그 대신 스바네티 트레킹 3박(자베시·아디시·이프랄리)이 들어갔습니다.
A32: 트레킹 3박은 게스트하우스 저녁·아침 포함 85라리(45,985원) 기준입니다(2026년 1월 자료). 그래서 9/24·9/25 식비는 도시락·간식값 15,000원만 잡았습니다.
A33: 카즈베기 1박 · 예레반 3박 구성입니다. 카즈베기 산악 택시가 줄어든 만큼 예레반 숙박 1박(20,000원)이 늘어 거의 상쇄됩니다.
A34: 가는 야간버스가 결항해 직행 마르슈르트카로 대체하면 트빌리시 숙소 1박(15,689원)이 늘고 교통비는 25라리 줄어듭니다.
A35: ※ 여행자보험·유심·기념품은 별도로 잡으세요. 스바네티 소금과 조지아 와인이 주요 지출처입니다.
A36: ※ 아르메니아 나흘을 다시 짜면서 교통·입장료가 20,800드람(약 80,704원) 늘었습니다 — 9/29 택시 · 9/30 에치미아진·즈바르트노츠 · 10/2 호르 비랍. 아흐탈라 수도원과 아라라트 브랜디 공장은 예비비 때문에 넣지 않았습니다.
